try{

} catch(Exceptione) {

} catch(ArithmeticExceptiona) {

}

funktioniert nicht, da catch nur nach try kommen kann. In dem Fall kommt catch nach catch.
